nohup: ignoring input
New https://pypi.org/project/ultralytics/8.3.65 available üòÉ Update with 'pip install -U ultralytics'
Ultralytics 8.3.63 üöÄ Python-3.8.12 torch-2.4.1+cu121 CUDA:0 (NVIDIA GeForce RTX 3090, 24260MiB)
[34m[1mengine/trainer: [0mtask=detect, mode=train, model=best_2.pt, data=basketball_last/data.yaml, epochs=50, time=None, patience=20, batch=64, imgsz=640, save=True, save_period=-1, cache=False, device=0, workers=8, project=None, name=new_basketball_model6, exist_ok=False, pretrained=True, optimizer=auto, verbose=True, seed=0, deterministic=True, single_cls=False, rect=False, cos_lr=False, close_mosaic=10, resume=False, amp=True, fraction=1.0, profile=False, freeze=None, multi_scale=False, overlap_mask=True, mask_ratio=4, dropout=0.0, val=True, split=val, save_json=False, save_hybrid=False, conf=None, iou=0.7, max_det=300, half=False, dnn=False, plots=True, source=None, vid_stride=1, stream_buffer=False, visualize=False, augment=False, agnostic_nms=False, classes=None, retina_masks=False, embed=None, show=False, save_frames=False, save_txt=False, save_conf=False, save_crop=False, show_labels=True, show_conf=True, show_boxes=True, line_width=None, format=torchscript, keras=False, optimize=False, int8=False, dynamic=False, simplify=True, opset=None, workspace=None, nms=False, lr0=0.01, lrf=0.01, momentum=0.937, weight_decay=0.0005, warmup_epochs=3.0, warmup_momentum=0.8, warmup_bias_lr=0.1, box=7.5, cls=0.5, dfl=1.5, pose=12.0, kobj=1.0, nbs=64, hsv_h=0.015, hsv_s=0.7, hsv_v=0.4, degrees=0.0, translate=0.1, scale=0.5, shear=0.0, perspective=0.0, flipud=0.0, fliplr=0.5, bgr=0.0, mosaic=1.0, mixup=0.0, copy_paste=0.0, copy_paste_mode=flip, auto_augment=randaugment, erasing=0.4, crop_fraction=1.0, cfg=None, tracker=botsort.yaml, save_dir=/root/.pyenv/runs/detect/new_basketball_model6
Traceback (most recent call last):
  File "/root/.pyenv/versions/3.8.12/lib/python3.8/site-packages/ultralytics/engine/trainer.py", line 563, in get_dataset
    data = check_det_dataset(self.args.data)
  File "/root/.pyenv/versions/3.8.12/lib/python3.8/site-packages/ultralytics/data/utils.py", line 316, in check_det_dataset
    file = check_file(dataset)
  File "/root/.pyenv/versions/3.8.12/lib/python3.8/site-packages/ultralytics/utils/checks.py", line 520, in check_file
    raise FileNotFoundError(f"'{file}' does not exist")
FileNotFoundError: 'basketball_last/data.yaml' does not exist

The above exception was the direct cause of the following exception:

Traceback (most recent call last):
  File "/root/.pyenv/versions/3.8.12/bin/yolo", line 8, in <module>
    sys.exit(entrypoint())
  File "/root/.pyenv/versions/3.8.12/lib/python3.8/site-packages/ultralytics/cfg/__init__.py", line 983, in entrypoint
    getattr(model, mode)(**overrides)  # default args from model
  File "/root/.pyenv/versions/3.8.12/lib/python3.8/site-packages/ultralytics/engine/model.py", line 800, in train
    self.trainer = (trainer or self._smart_load("trainer"))(overrides=args, _callbacks=self.callbacks)
  File "/root/.pyenv/versions/3.8.12/lib/python3.8/site-packages/ultralytics/engine/trainer.py", line 133, in __init__
    self.trainset, self.testset = self.get_dataset()
  File "/root/.pyenv/versions/3.8.12/lib/python3.8/site-packages/ultralytics/engine/trainer.py", line 567, in get_dataset
    raise RuntimeError(emojis(f"Dataset '{clean_url(self.args.data)}' error ‚ùå {e}")) from e
RuntimeError: Dataset 'basketball_last/data.yaml' error ‚ùå 'basketball_last/data.yaml' does not exist
